[2025-01-22T07:36:13.897+0000] {local_task_job_runner.py:123} INFO - ::group::Pre task execution logs
[2025-01-22T07:36:13.920+0000] {taskinstance.py:2613} INFO - Dependencies all met for dep_context=non-requeueable deps ti=<TaskInstance: joe_rogan_youtube_data.extract_jre_data manual__2025-01-22T07:35:29.734216+00:00 [queued]>
[2025-01-22T07:36:13.927+0000] {taskinstance.py:2613} INFO - Dependencies all met for dep_context=requeueable deps ti=<TaskInstance: joe_rogan_youtube_data.extract_jre_data manual__2025-01-22T07:35:29.734216+00:00 [queued]>
[2025-01-22T07:36:13.927+0000] {taskinstance.py:2866} INFO - Starting attempt 1 of 5
[2025-01-22T07:36:13.938+0000] {taskinstance.py:2889} INFO - Executing <Task(PythonOperator): extract_jre_data> on 2025-01-22 07:35:29.734216+00:00
[2025-01-22T07:36:13.946+0000] {standard_task_runner.py:72} INFO - Started process 49 to run task
[2025-01-22T07:36:13.952+0000] {standard_task_runner.py:104} INFO - Running: ['airflow', 'tasks', 'run', 'joe_rogan_youtube_data', 'extract_jre_data', 'manual__2025-01-22T07:35:29.734216+00:00', '--job-id', '3', '--raw', '--subdir', 'DAGS_FOLDER/joe_rogan_youtube_channel.py', '--cfg-path', '/tmp/tmpdvzsqxz0']
[2025-01-22T07:36:13.959+0000] {standard_task_runner.py:105} INFO - Job 3: Subtask extract_jre_data
[2025-01-22T07:36:14.030+0000] {task_command.py:467} INFO - Running <TaskInstance: joe_rogan_youtube_data.extract_jre_data manual__2025-01-22T07:35:29.734216+00:00 [running]> on host aeb082a32b59
[2025-01-22T07:36:14.124+0000] {taskinstance.py:3132} INFO - Exporting env vars: AIRFLOW_CTX_DAG_OWNER='Ballal' AIRFLOW_CTX_DAG_ID='joe_rogan_youtube_data' AIRFLOW_CTX_TASK_ID='extract_jre_data' AIRFLOW_CTX_EXECUTION_DATE='2025-01-22T07:35:29.734216+00:00' AIRFLOW_CTX_TRY_NUMBER='1' AIRFLOW_CTX_DAG_RUN_ID='manual__2025-01-22T07:35:29.734216+00:00'
[2025-01-22T07:36:14.126+0000] {taskinstance.py:731} INFO - ::endgroup::
[2025-01-22T07:36:14.143+0000] {__init__.py:49} INFO - file_cache is only supported with oauth2client<4.0.0
[2025-01-22T07:36:24.080+0000] {local_task_job_runner.py:346} WARNING - State of this instance has been externally set to None. Terminating instance.
[2025-01-22T07:36:24.082+0000] {local_task_job_runner.py:245} INFO - ::endgroup::
[2025-01-22T07:36:24.083+0000] {process_utils.py:132} INFO - Sending 15 to group 49. PIDs of all processes in the group: [49]
[2025-01-22T07:36:24.083+0000] {process_utils.py:87} INFO - Sending the signal 15 to group 49
[2025-01-22T07:36:24.084+0000] {taskinstance.py:3093} ERROR - Received SIGTERM. Terminating subprocesses.
[2025-01-22T07:36:24.097+0000] {taskinstance.py:3311} ERROR - Task failed with exception
Traceback (most recent call last):
  File "/home/airflow/.local/lib/python3.11/site-packages/airflow/models/taskinstance.py", line 767, in _execute_task
    result = _execute_callable(context=context, **execute_callable_kwargs)
             ^^^^^^^^^^^^^^^^^^^^^^^^^^^^^^^^^^^^^^^^^^^^^^^^^^^^^^^^^^^^^
  File "/home/airflow/.local/lib/python3.11/site-packages/airflow/models/taskinstance.py", line 733, in _execute_callable
    return ExecutionCallableRunner(
           ^^^^^^^^^^^^^^^^^^^^^^^^
  File "/home/airflow/.local/lib/python3.11/site-packages/airflow/utils/operator_helpers.py", line 252, in run
    return self.func(*args, **kwargs)
           ^^^^^^^^^^^^^^^^^^^^^^^^^^
  File "/home/airflow/.local/lib/python3.11/site-packages/airflow/models/baseoperator.py", line 422, in wrapper
    return func(self, *args, **kwargs)
           ^^^^^^^^^^^^^^^^^^^^^^^^^^^
  File "/home/airflow/.local/lib/python3.11/site-packages/airflow/operators/python.py", line 238, in execute
    return_value = self.execute_callable()
                   ^^^^^^^^^^^^^^^^^^^^^^^
  File "/home/airflow/.local/lib/python3.11/site-packages/airflow/operators/python.py", line 256, in execute_callable
    return runner.run(*self.op_args, **self.op_kwargs)
           ^^^^^^^^^^^^^^^^^^^^^^^^^^^^^^^^^^^^^^^^^^^
  File "/home/airflow/.local/lib/python3.11/site-packages/airflow/utils/operator_helpers.py", line 252, in run
    return self.func(*args, **kwargs)
           ^^^^^^^^^^^^^^^^^^^^^^^^^^
  File "/opt/airflow/dags/joe_rogan_youtube_channel.py", line 100, in extract_jre_data
    videos = fetch_channel_videos(api_key, channel_id)
             ^^^^^^^^^^^^^^^^^^^^^^^^^^^^^^^^^^^^^^^^^
  File "/opt/airflow/dags/joe_rogan_youtube_channel.py", line 68, in fetch_channel_videos
    videos.extend(fetch_video_details(youtube, video_ids))
                  ^^^^^^^^^^^^^^^^^^^^^^^^^^^^^^^^^^^^^^^
  File "/opt/airflow/dags/joe_rogan_youtube_channel.py", line 24, in fetch_video_details
    video_response = video_request.execute()
                     ^^^^^^^^^^^^^^^^^^^^^^^
  File "/home/airflow/.local/lib/python3.11/site-packages/googleapiclient/_helpers.py", line 130, in positional_wrapper
    return wrapped(*args, **kwargs)
           ^^^^^^^^^^^^^^^^^^^^^^^^
  File "/home/airflow/.local/lib/python3.11/site-packages/googleapiclient/http.py", line 923, in execute
    resp, content = _retry_request(
                    ^^^^^^^^^^^^^^^
  File "/home/airflow/.local/lib/python3.11/site-packages/googleapiclient/http.py", line 191, in _retry_request
    resp, content = http.request(uri, method, *args, **kwargs)
                    ^^^^^^^^^^^^^^^^^^^^^^^^^^^^^^^^^^^^^^^^^^
  File "/home/airflow/.local/lib/python3.11/site-packages/httplib2/__init__.py", line 1724, in request
    (response, content) = self._request(
                          ^^^^^^^^^^^^^^
  File "/home/airflow/.local/lib/python3.11/site-packages/httplib2/__init__.py", line 1444, in _request
    (response, content) = self._conn_request(conn, request_uri, method, body, headers)
                          ^^^^^^^^^^^^^^^^^^^^^^^^^^^^^^^^^^^^^^^^^^^^^^^^^^^^^^^^^^^^
  File "/home/airflow/.local/lib/python3.11/site-packages/httplib2/__init__.py", line 1396, in _conn_request
    response = conn.getresponse()
               ^^^^^^^^^^^^^^^^^^
  File "/usr/local/lib/python3.11/http/client.py", line 1378, in getresponse
    response.begin()
  File "/usr/local/lib/python3.11/http/client.py", line 318, in begin
    version, status, reason = self._read_status()
                              ^^^^^^^^^^^^^^^^^^^
  File "/usr/local/lib/python3.11/http/client.py", line 279, in _read_status
    line = str(self.fp.readline(_MAXLINE + 1), "iso-8859-1")
               ^^^^^^^^^^^^^^^^^^^^^^^^^^^^^^
  File "/usr/local/lib/python3.11/socket.py", line 706, in readinto
    return self._sock.recv_into(b)
           ^^^^^^^^^^^^^^^^^^^^^^^
  File "/usr/local/lib/python3.11/ssl.py", line 1311, in recv_into
    return self.read(nbytes, buffer)
           ^^^^^^^^^^^^^^^^^^^^^^^^^
  File "/usr/local/lib/python3.11/ssl.py", line 1167, in read
    return self._sslobj.read(len, buffer)
           ^^^^^^^^^^^^^^^^^^^^^^^^^^^^^^
  File "/home/airflow/.local/lib/python3.11/site-packages/airflow/models/taskinstance.py", line 3095, in signal_handler
    raise AirflowTaskTerminated("Task received SIGTERM signal")
airflow.exceptions.AirflowTaskTerminated: Task received SIGTERM signal
[2025-01-22T07:36:24.105+0000] {taskinstance.py:1225} INFO - Marking task as UP_FOR_RETRY. dag_id=joe_rogan_youtube_data, task_id=extract_jre_data, run_id=manual__2025-01-22T07:35:29.734216+00:00, execution_date=20250122T073529, start_date=20250122T073613, end_date=20250122T073624
[2025-01-22T07:36:24.115+0000] {taskinstance.py:340} INFO - ::group::Post task execution logs
[2025-01-22T07:36:24.116+0000] {standard_task_runner.py:124} ERROR - Failed to execute job 3 for task extract_jre_data ((psycopg2.errors.ForeignKeyViolation) insert or update on table "task_fail" violates foreign key constraint "task_fail_ti_fkey"
DETAIL:  Key (dag_id, task_id, run_id, map_index)=(joe_rogan_youtube_data, extract_jre_data, manual__2025-01-22T07:35:29.734216+00:00, -1) is not present in table "task_instance".

[SQL: INSERT INTO task_fail (task_id, dag_id, run_id, map_index, start_date, end_date, duration) VALUES (%(task_id)s, %(dag_id)s, %(run_id)s, %(map_index)s, %(start_date)s, %(end_date)s, %(duration)s) RETURNING task_fail.id]
[parameters: {'task_id': 'extract_jre_data', 'dag_id': 'joe_rogan_youtube_data', 'run_id': 'manual__2025-01-22T07:35:29.734216+00:00', 'map_index': -1, 'start_date': datetime.datetime(2025, 1, 22, 7, 36, 13, 920727, tzinfo=Timezone('UTC')), 'end_date': datetime.datetime(2025, 1, 22, 7, 36, 24, 104755, tzinfo=Timezone('UTC')), 'duration': 10}]
(Background on this error at: https://sqlalche.me/e/14/gkpj); 49)
Traceback (most recent call last):
  File "/home/airflow/.local/lib/python3.11/site-packages/airflow/models/taskinstance.py", line 273, in _run_raw_task
    TaskInstance._execute_task_with_callbacks(
  File "/home/airflow/.local/lib/python3.11/site-packages/airflow/models/taskinstance.py", line 3159, in _execute_task_with_callbacks
    result = self._execute_task(context, task_orig)
             ^^^^^^^^^^^^^^^^^^^^^^^^^^^^^^^^^^^^^^
  File "/home/airflow/.local/lib/python3.11/site-packages/airflow/models/taskinstance.py", line 3183, in _execute_task
    return _execute_task(self, context, task_orig)
           ^^^^^^^^^^^^^^^^^^^^^^^^^^^^^^^^^^^^^^^
  File "/home/airflow/.local/lib/python3.11/site-packages/airflow/models/taskinstance.py", line 767, in _execute_task
    result = _execute_callable(context=context, **execute_callable_kwargs)
             ^^^^^^^^^^^^^^^^^^^^^^^^^^^^^^^^^^^^^^^^^^^^^^^^^^^^^^^^^^^^^
  File "/home/airflow/.local/lib/python3.11/site-packages/airflow/models/taskinstance.py", line 733, in _execute_callable
    return ExecutionCallableRunner(
           ^^^^^^^^^^^^^^^^^^^^^^^^
  File "/home/airflow/.local/lib/python3.11/site-packages/airflow/utils/operator_helpers.py", line 252, in run
    return self.func(*args, **kwargs)
           ^^^^^^^^^^^^^^^^^^^^^^^^^^
  File "/home/airflow/.local/lib/python3.11/site-packages/airflow/models/baseoperator.py", line 422, in wrapper
    return func(self, *args, **kwargs)
           ^^^^^^^^^^^^^^^^^^^^^^^^^^^
  File "/home/airflow/.local/lib/python3.11/site-packages/airflow/operators/python.py", line 238, in execute
    return_value = self.execute_callable()
                   ^^^^^^^^^^^^^^^^^^^^^^^
  File "/home/airflow/.local/lib/python3.11/site-packages/airflow/operators/python.py", line 256, in execute_callable
    return runner.run(*self.op_args, **self.op_kwargs)
           ^^^^^^^^^^^^^^^^^^^^^^^^^^^^^^^^^^^^^^^^^^^
  File "/home/airflow/.local/lib/python3.11/site-packages/airflow/utils/operator_helpers.py", line 252, in run
    return self.func(*args, **kwargs)
           ^^^^^^^^^^^^^^^^^^^^^^^^^^
  File "/opt/airflow/dags/joe_rogan_youtube_channel.py", line 100, in extract_jre_data
    videos = fetch_channel_videos(api_key, channel_id)
             ^^^^^^^^^^^^^^^^^^^^^^^^^^^^^^^^^^^^^^^^^
  File "/opt/airflow/dags/joe_rogan_youtube_channel.py", line 68, in fetch_channel_videos
    videos.extend(fetch_video_details(youtube, video_ids))
                  ^^^^^^^^^^^^^^^^^^^^^^^^^^^^^^^^^^^^^^^
  File "/opt/airflow/dags/joe_rogan_youtube_channel.py", line 24, in fetch_video_details
    video_response = video_request.execute()
                     ^^^^^^^^^^^^^^^^^^^^^^^
  File "/home/airflow/.local/lib/python3.11/site-packages/googleapiclient/_helpers.py", line 130, in positional_wrapper
    return wrapped(*args, **kwargs)
           ^^^^^^^^^^^^^^^^^^^^^^^^
  File "/home/airflow/.local/lib/python3.11/site-packages/googleapiclient/http.py", line 923, in execute
    resp, content = _retry_request(
                    ^^^^^^^^^^^^^^^
  File "/home/airflow/.local/lib/python3.11/site-packages/googleapiclient/http.py", line 191, in _retry_request
    resp, content = http.request(uri, method, *args, **kwargs)
                    ^^^^^^^^^^^^^^^^^^^^^^^^^^^^^^^^^^^^^^^^^^
  File "/home/airflow/.local/lib/python3.11/site-packages/httplib2/__init__.py", line 1724, in request
    (response, content) = self._request(
                          ^^^^^^^^^^^^^^
  File "/home/airflow/.local/lib/python3.11/site-packages/httplib2/__init__.py", line 1444, in _request
    (response, content) = self._conn_request(conn, request_uri, method, body, headers)
                          ^^^^^^^^^^^^^^^^^^^^^^^^^^^^^^^^^^^^^^^^^^^^^^^^^^^^^^^^^^^^
  File "/home/airflow/.local/lib/python3.11/site-packages/httplib2/__init__.py", line 1396, in _conn_request
    response = conn.getresponse()
               ^^^^^^^^^^^^^^^^^^
  File "/usr/local/lib/python3.11/http/client.py", line 1378, in getresponse
    response.begin()
  File "/usr/local/lib/python3.11/http/client.py", line 318, in begin
    version, status, reason = self._read_status()
                              ^^^^^^^^^^^^^^^^^^^
  File "/usr/local/lib/python3.11/http/client.py", line 279, in _read_status
    line = str(self.fp.readline(_MAXLINE + 1), "iso-8859-1")
               ^^^^^^^^^^^^^^^^^^^^^^^^^^^^^^
  File "/usr/local/lib/python3.11/socket.py", line 706, in readinto
    return self._sock.recv_into(b)
           ^^^^^^^^^^^^^^^^^^^^^^^
  File "/usr/local/lib/python3.11/ssl.py", line 1311, in recv_into
    return self.read(nbytes, buffer)
           ^^^^^^^^^^^^^^^^^^^^^^^^^
  File "/usr/local/lib/python3.11/ssl.py", line 1167, in read
    return self._sslobj.read(len, buffer)
           ^^^^^^^^^^^^^^^^^^^^^^^^^^^^^^
  File "/home/airflow/.local/lib/python3.11/site-packages/airflow/models/taskinstance.py", line 3095, in signal_handler
    raise AirflowTaskTerminated("Task received SIGTERM signal")
airflow.exceptions.AirflowTaskTerminated: Task received SIGTERM signal

During handling of the above exception, another exception occurred:

Traceback (most recent call last):
  File "/home/airflow/.local/lib/python3.11/site-packages/sqlalchemy/engine/base.py", line 1910, in _execute_context
    self.dialect.do_execute(
  File "/home/airflow/.local/lib/python3.11/site-packages/sqlalchemy/engine/default.py", line 736, in do_execute
    cursor.execute(statement, parameters)
psycopg2.errors.ForeignKeyViolation: insert or update on table "task_fail" violates foreign key constraint "task_fail_ti_fkey"
DETAIL:  Key (dag_id, task_id, run_id, map_index)=(joe_rogan_youtube_data, extract_jre_data, manual__2025-01-22T07:35:29.734216+00:00, -1) is not present in table "task_instance".


The above exception was the direct cause of the following exception:

Traceback (most recent call last):
  File "/home/airflow/.local/lib/python3.11/site-packages/airflow/task/task_runner/standard_task_runner.py", line 117, in _start_by_fork
    ret = args.func(args, dag=self.dag)
          ^^^^^^^^^^^^^^^^^^^^^^^^^^^^^
  File "/home/airflow/.local/lib/python3.11/site-packages/airflow/cli/cli_config.py", line 49, in command
    return func(*args, **kwargs)
           ^^^^^^^^^^^^^^^^^^^^^
  File "/home/airflow/.local/lib/python3.11/site-packages/airflow/utils/cli.py", line 116, in wrapper
    return f(*args, **kwargs)
           ^^^^^^^^^^^^^^^^^^
  File "/home/airflow/.local/lib/python3.11/site-packages/airflow/cli/commands/task_command.py", line 483, in task_run
    task_return_code = _run_task_by_selected_method(args, _dag, ti)
                       ^^^^^^^^^^^^^^^^^^^^^^^^^^^^^^^^^^^^^^^^^^^^
  File "/home/airflow/.local/lib/python3.11/site-packages/airflow/cli/commands/task_command.py", line 256, in _run_task_by_selected_method
    return _run_raw_task(args, ti)
           ^^^^^^^^^^^^^^^^^^^^^^^
  File "/home/airflow/.local/lib/python3.11/site-packages/airflow/cli/commands/task_command.py", line 341, in _run_raw_task
    return ti._run_raw_task(
           ^^^^^^^^^^^^^^^^^
  File "/home/airflow/.local/lib/python3.11/site-packages/airflow/utils/session.py", line 97, in wrapper
    return func(*args, session=session, **kwargs)
           ^^^^^^^^^^^^^^^^^^^^^^^^^^^^^^^^^^^^^^
  File "/home/airflow/.local/lib/python3.11/site-packages/airflow/models/taskinstance.py", line 3005, in _run_raw_task
    return _run_raw_task(
           ^^^^^^^^^^^^^^
  File "/home/airflow/.local/lib/python3.11/site-packages/airflow/models/taskinstance.py", line 327, in _run_raw_task
    ti.handle_failure(e, test_mode, context, session=session)
  File "/home/airflow/.local/lib/python3.11/site-packages/airflow/utils/session.py", line 94, in wrapper
    return func(*args, **kwargs)
           ^^^^^^^^^^^^^^^^^^^^^
  File "/home/airflow/.local/lib/python3.11/site-packages/airflow/models/taskinstance.py", line 3428, in handle_failure
    _handle_failure(
  File "/home/airflow/.local/lib/python3.11/site-packages/airflow/utils/session.py", line 94, in wrapper
    return func(*args, **kwargs)
           ^^^^^^^^^^^^^^^^^^^^^
  File "/home/airflow/.local/lib/python3.11/site-packages/airflow/api_internal/internal_api_call.py", line 166, in wrapper
    return func(*args, **kwargs)
           ^^^^^^^^^^^^^^^^^^^^^
  File "/home/airflow/.local/lib/python3.11/site-packages/airflow/models/taskinstance.py", line 1243, in _handle_failure
    TaskInstance.save_to_db(failure_context["ti"], session)
  File "/home/airflow/.local/lib/python3.11/site-packages/airflow/api_internal/internal_api_call.py", line 166, in wrapper
    return func(*args, **kwargs)
           ^^^^^^^^^^^^^^^^^^^^^
  File "/home/airflow/.local/lib/python3.11/site-packages/airflow/utils/session.py", line 94, in wrapper
    return func(*args, **kwargs)
           ^^^^^^^^^^^^^^^^^^^^^
  File "/home/airflow/.local/lib/python3.11/site-packages/airflow/models/taskinstance.py", line 3400, in save_to_db
    session.flush()
  File "/home/airflow/.local/lib/python3.11/site-packages/sqlalchemy/orm/session.py", line 3449, in flush
    self._flush(objects)
  File "/home/airflow/.local/lib/python3.11/site-packages/sqlalchemy/orm/session.py", line 3588, in _flush
    with util.safe_reraise():
  File "/home/airflow/.local/lib/python3.11/site-packages/sqlalchemy/util/langhelpers.py", line 70, in __exit__
    compat.raise_(
  File "/home/airflow/.local/lib/python3.11/site-packages/sqlalchemy/util/compat.py", line 211, in raise_
    raise exception
  File "/home/airflow/.local/lib/python3.11/site-packages/sqlalchemy/orm/session.py", line 3549, in _flush
    flush_context.execute()
  File "/home/airflow/.local/lib/python3.11/site-packages/sqlalchemy/orm/unitofwork.py", line 456, in execute
    rec.execute(self)
  File "/home/airflow/.local/lib/python3.11/site-packages/sqlalchemy/orm/unitofwork.py", line 630, in execute
    util.preloaded.orm_persistence.save_obj(
  File "/home/airflow/.local/lib/python3.11/site-packages/sqlalchemy/orm/persistence.py", line 245, in save_obj
    _emit_insert_statements(
  File "/home/airflow/.local/lib/python3.11/site-packages/sqlalchemy/orm/persistence.py", line 1238, in _emit_insert_statements
    result = connection._execute_20(
             ^^^^^^^^^^^^^^^^^^^^^^^
  File "/home/airflow/.local/lib/python3.11/site-packages/sqlalchemy/engine/base.py", line 1710, in _execute_20
    return meth(self, args_10style, kwargs_10style, execution_options)
           ^^^^^^^^^^^^^^^^^^^^^^^^^^^^^^^^^^^^^^^^^^^^^^^^^^^^^^^^^^^
  File "/home/airflow/.local/lib/python3.11/site-packages/sqlalchemy/sql/elements.py", line 334, in _execute_on_connection
    return connection._execute_clauseelement(
           ^^^^^^^^^^^^^^^^^^^^^^^^^^^^^^^^^^
  File "/home/airflow/.local/lib/python3.11/site-packages/sqlalchemy/engine/base.py", line 1577, in _execute_clauseelement
    ret = self._execute_context(
          ^^^^^^^^^^^^^^^^^^^^^^
  File "/home/airflow/.local/lib/python3.11/site-packages/sqlalchemy/engine/base.py", line 1953, in _execute_context
    self._handle_dbapi_exception(
  File "/home/airflow/.local/lib/python3.11/site-packages/sqlalchemy/engine/base.py", line 2134, in _handle_dbapi_exception
    util.raise_(
  File "/home/airflow/.local/lib/python3.11/site-packages/sqlalchemy/util/compat.py", line 211, in raise_
    raise exception
  File "/home/airflow/.local/lib/python3.11/site-packages/sqlalchemy/engine/base.py", line 1910, in _execute_context
    self.dialect.do_execute(
  File "/home/airflow/.local/lib/python3.11/site-packages/sqlalchemy/engine/default.py", line 736, in do_execute
    cursor.execute(statement, parameters)
sqlalchemy.exc.IntegrityError: (psycopg2.errors.ForeignKeyViolation) insert or update on table "task_fail" violates foreign key constraint "task_fail_ti_fkey"
DETAIL:  Key (dag_id, task_id, run_id, map_index)=(joe_rogan_youtube_data, extract_jre_data, manual__2025-01-22T07:35:29.734216+00:00, -1) is not present in table "task_instance".

[SQL: INSERT INTO task_fail (task_id, dag_id, run_id, map_index, start_date, end_date, duration) VALUES (%(task_id)s, %(dag_id)s, %(run_id)s, %(map_index)s, %(start_date)s, %(end_date)s, %(duration)s) RETURNING task_fail.id]
[parameters: {'task_id': 'extract_jre_data', 'dag_id': 'joe_rogan_youtube_data', 'run_id': 'manual__2025-01-22T07:35:29.734216+00:00', 'map_index': -1, 'start_date': datetime.datetime(2025, 1, 22, 7, 36, 13, 920727, tzinfo=Timezone('UTC')), 'end_date': datetime.datetime(2025, 1, 22, 7, 36, 24, 104755, tzinfo=Timezone('UTC')), 'duration': 10}]
(Background on this error at: https://sqlalche.me/e/14/gkpj)
[2025-01-22T07:36:24.136+0000] {process_utils.py:80} INFO - Process psutil.Process(pid=49, status='terminated', exitcode=1, started='07:36:13') (49) terminated with exit code 1
